<robot name="onshape">
    <link name="node:1">
        <visual>
            <origin xyz="-0.010479 0.0475077 0.036402" rpy="0.785396 -0.590722 0.492745" />
            <geometry>
                <mesh filename="package://node:1.stl"/>
            </geometry>
            <material name="node:1_material">
                <color rgba="1 0 0 1.0"/>
            </material>
        </visual>
        <collision>
            <origin xyz="-0.010479 0.0475077 0.036402" rpy="0.785396 -0.590722 0.492745" />
            <geometry>
                <mesh filename="package://node:1.stl"/>
            </geometry>
            <material name="node:1_material">
                <color rgba="1 0 0 1.0"/>
            </material>
        </collision>
        <inertial>
            <origin xyz="-0.010479 0.0475077 0.036402" rpy="0 0 0"/>
            <mass value="4.40661" />
            <inertia ixx="0.0176264" ixy="-2.60209e-17" ixz="2.1684e-17" iyy="0.0176264" iyz="6.85216e-17" izz="0.0176264" />
        </inertial>
    </link>

    <link name="dummy_joint:1">
        <visual>
            <origin xyz="0 6.93889e-18 0" rpy="3.14159 5.55112e-17 5.55112e-17" />
            <geometry>
                <mesh filename="package://dummy_joint:1.stl"/>
            </geometry>
            <material name="dummy_joint:1_material">
                <color rgba="0.972549 0.529412 0.00392157 1.0"/>
            </material>
        </visual>
        <collision>
            <origin xyz="0 6.93889e-18 0" rpy="3.14159 5.55112e-17 5.55112e-17" />
            <geometry>
                <mesh filename="package://dummy_joint:1.stl"/>
            </geometry>
            <material name="dummy_joint:1_material">
                <color rgba="0.972549 0.529412 0.00392157 1.0"/>
            </material>
        </collision>
        <inertial>
            <origin xyz="6.97884e-19 7.65304e-18 -0.00201266" rpy="0 0 0"/>
            <mass value="0.24179" />
            <inertia ixx="0.000251433" ixy="2.39242e-21" ixz="-8.89725e-21" iyy="0.000208335" iyz="-7.4525e-21" izz="0.000342587" />
        </inertial>
    </link>

    <link name="member:1">
        <visual>
            <origin xyz="-1.73472e-18 -4.16334e-17 -0.0133333" rpy="1.5708 1.5708 0" />
            <geometry>
                <mesh filename="package://member:1.stl"/>
            </geometry>
            <material name="member:1_material">
                <color rgba="0.717647 0.717647 0.717647 1.0"/>
            </material>
        </visual>
        <collision>
            <origin xyz="-1.73472e-18 -4.16334e-17 -0.0133333" rpy="1.5708 1.5708 0" />
            <geometry>
                <mesh filename="package://member:1.stl"/>
            </geometry>
            <material name="member:1_material">
                <color rgba="0.717647 0.717647 0.717647 1.0"/>
            </material>
        </collision>
        <inertial>
            <origin xyz="1.77997e-08 -0.514694 -0.0133333" rpy="0 0 0"/>
            <mass value="5.12617" />
            <inertia ixx="0.00413002" ixy="-4.52589e-09" ixz="3.46766e-08" iyy="0.406687" iyz="1.21553e-09" izz="0.406597" />
        </inertial>
    </link>

    <link name="member:1_2">
        <visual>
            <origin xyz="3.46945e-17 -3.81639e-17 -1" rpy="2.68137e-17 -2.3168e-17 -5.55112e-17" />
            <geometry>
                <mesh filename="package://member:1.stl"/>
            </geometry>
            <material name="member:1_material">
                <color rgba="0.717647 0.717647 0.717647 1.0"/>
            </material>
        </visual>
        <collision>
            <origin xyz="3.46945e-17 -3.81639e-17 -1" rpy="2.68137e-17 -2.3168e-17 -5.55112e-17" />
            <geometry>
                <mesh filename="package://member:1.stl"/>
            </geometry>
            <material name="member:1_material">
                <color rgba="0.717647 0.717647 0.717647 1.0"/>
            </material>
        </collision>
        <inertial>
            <origin xyz="8.227e-09 1.77997e-08 -0.485306" rpy="0 0 0"/>
            <mass value="5.12617" />
            <inertia ixx="0.406687" ixy="-1.21553e-09" ixz="4.52589e-09" iyy="0.406597" iyz="3.46766e-08" izz="0.00413002" />
        </inertial>
    </link>

    <link name="dummy_joint:1_2">
        <visual>
            <origin xyz="2.22045e-16 0 -0.0133333" rpy="-1.5708 -1.5708 0" />
            <geometry>
                <mesh filename="package://dummy_joint:1.stl"/>
            </geometry>
            <material name="dummy_joint:1_material">
                <color rgba="0.972549 0.529412 0.00392157 1.0"/>
            </material>
        </visual>
        <collision>
            <origin xyz="2.22045e-16 0 -0.0133333" rpy="-1.5708 -1.5708 0" />
            <geometry>
                <mesh filename="package://dummy_joint:1.stl"/>
            </geometry>
            <material name="dummy_joint:1_material">
                <color rgba="0.972549 0.529412 0.00392157 1.0"/>
            </material>
        </collision>
        <inertial>
            <origin xyz="2.21219e-16 0.00201266 -0.0133333" rpy="0 0 0"/>
            <mass value="0.24179" />
            <inertia ixx="0.000342587" ixy="-1.90174e-20" ixz="3.80348e-20" iyy="0.000251433" iyz="-2.11136e-36" izz="0.000208335" />
        </inertial>
    </link>

    <link name="node:1_2">
        <visual>
            <origin xyz="-1.11022e-16 0 2.22045e-16" rpy="5.55112e-17 -0 0" />
            <geometry>
                <mesh filename="package://node:1.stl"/>
            </geometry>
            <material name="node:1_material">
                <color rgba="1 0 0 1.0"/>
            </material>
        </visual>
        <collision>
            <origin xyz="-1.11022e-16 0 2.22045e-16" rpy="5.55112e-17 -0 0" />
            <geometry>
                <mesh filename="package://node:1.stl"/>
            </geometry>
            <material name="node:1_material">
                <color rgba="1 0 0 1.0"/>
            </material>
        </collision>
        <inertial>
            <origin xyz="-1.13319e-16 0 2.22045e-16" rpy="0 0 0"/>
            <mass value="4.40661" />
            <inertia ixx="0.0176264" ixy="-9.78463e-19" ixz="9.78463e-19" iyy="0.0176264" iyz="4.89232e-19" izz="0.0176264" />
        </inertial>
    </link>

    <link name="dummy_joint:1_3">
        <visual>
            <origin xyz="-2.22045e-16 2.08167e-17 0" rpy="3.14159 1.11022e-16 0" />
            <geometry>
                <mesh filename="package://dummy_joint:1.stl"/>
            </geometry>
            <material name="dummy_joint:1_material">
                <color rgba="0.972549 0.529412 0.00392157 1.0"/>
            </material>
        </visual>
        <collision>
            <origin xyz="-2.22045e-16 2.08167e-17 0" rpy="3.14159 1.11022e-16 0" />
            <geometry>
                <mesh filename="package://dummy_joint:1.stl"/>
            </geometry>
            <material name="dummy_joint:1_material">
                <color rgba="0.972549 0.529412 0.00392157 1.0"/>
            </material>
        </collision>
        <inertial>
            <origin xyz="-2.21012e-16 2.16426e-17 -0.00201266" rpy="0 0 0"/>
            <mass value="0.24179" />
            <inertia ixx="0.000251433" ixy="-2.11136e-36" ixz="5.19921e-20" iyy="0.000208335" iyz="-1.90174e-20" izz="0.000342587" />
        </inertial>
    </link>

    <link name="member:1_3">
        <visual>
            <origin xyz="0 -1.11022e-16 -0.0133333" rpy="-1.5708 -1.5708 0" />
            <geometry>
                <mesh filename="package://member:1.stl"/>
            </geometry>
            <material name="member:1_material">
                <color rgba="0.717647 0.717647 0.717647 1.0"/>
            </material>
        </visual>
        <collision>
            <origin xyz="0 -1.11022e-16 -0.0133333" rpy="-1.5708 -1.5708 0" />
            <geometry>
                <mesh filename="package://member:1.stl"/>
            </geometry>
            <material name="member:1_material">
                <color rgba="0.717647 0.717647 0.717647 1.0"/>
            </material>
        </collision>
        <inertial>
            <origin xyz="1.77997e-08 0.514694 -0.0133333" rpy="0 0 0"/>
            <mass value="5.12617" />
            <inertia ixx="0.00413002" ixy="4.52589e-09" ixz="3.46766e-08" iyy="0.406687" iyz="-1.21553e-09" izz="0.406597" />
        </inertial>
    </link>

    <link name="member:1_4">
        <visual>
            <origin xyz="-2.22045e-16 -1.11022e-16 -1" rpy="0 -1.35525e-20 5.55112e-17" />
            <geometry>
                <mesh filename="package://member:1.stl"/>
            </geometry>
            <material name="member:1_material">
                <color rgba="0.717647 0.717647 0.717647 1.0"/>
            </material>
        </visual>
        <collision>
            <origin xyz="-2.22045e-16 -1.11022e-16 -1" rpy="0 -1.35525e-20 5.55112e-17" />
            <geometry>
                <mesh filename="package://member:1.stl"/>
            </geometry>
            <material name="member:1_material">
                <color rgba="0.717647 0.717647 0.717647 1.0"/>
            </material>
        </collision>
        <inertial>
            <origin xyz="8.227e-09 1.77997e-08 -0.485306" rpy="0 0 0"/>
            <mass value="5.12617" />
            <inertia ixx="0.406687" ixy="-1.21553e-09" ixz="4.52589e-09" iyy="0.406597" iyz="3.46766e-08" izz="0.00413002" />
        </inertial>
    </link>

    <link name="dummy_joint:1_4">
        <visual>
            <origin xyz="-2.34188e-16 0 -0.0133333" rpy="1.5708 1.5708 0" />
            <geometry>
                <mesh filename="package://dummy_joint:1.stl"/>
            </geometry>
            <material name="dummy_joint:1_material">
                <color rgba="0.972549 0.529412 0.00392157 1.0"/>
            </material>
        </visual>
        <collision>
            <origin xyz="-2.34188e-16 0 -0.0133333" rpy="1.5708 1.5708 0" />
            <geometry>
                <mesh filename="package://dummy_joint:1.stl"/>
            </geometry>
            <material name="dummy_joint:1_material">
                <color rgba="0.972549 0.529412 0.00392157 1.0"/>
            </material>
        </collision>
        <inertial>
            <origin xyz="-2.34567e-16 -0.00201266 -0.0133333" rpy="0 0 0"/>
            <mass value="0.24179" />
            <inertia ixx="0.000342587" ixy="3.29747e-20" ixz="-3.80348e-20" iyy="0.000251433" iyz="4.42644e-20" izz="0.000208335" />
        </inertial>
    </link>

    <link name="node:1_3">
        <visual>
            <origin xyz="2.22045e-16 0 0" rpy="0 -2.77556e-17 -5.55112e-17" />
            <geometry>
                <mesh filename="package://node:1.stl"/>
            </geometry>
            <material name="node:1_material">
                <color rgba="1 0 0 1.0"/>
            </material>
        </visual>
        <collision>
            <origin xyz="2.22045e-16 0 0" rpy="0 -2.77556e-17 -5.55112e-17" />
            <geometry>
                <mesh filename="package://node:1.stl"/>
            </geometry>
            <material name="node:1_material">
                <color rgba="1 0 0 1.0"/>
            </material>
        </collision>
        <inertial>
            <origin xyz="2.19748e-16 1.27465e-34 -6.37327e-35" rpy="0 0 0"/>
            <mass value="4.40661" />
            <inertia ixx="0.0176264" ixy="-1.95693e-18" ixz="1.4677e-18" iyy="0.0176264" iyz="-5.43156e-35" izz="0.0176264" />
        </inertial>
    </link>

    <link name="dummy_joint:1_5">
        <visual>
            <origin xyz="1.80411e-16 2.22045e-16 0" rpy="3.14159 -0 0" />
            <geometry>
                <mesh filename="package://dummy_joint:1.stl"/>
            </geometry>
            <material name="dummy_joint:1_material">
                <color rgba="0.972549 0.529412 0.00392157 1.0"/>
            </material>
        </visual>
        <collision>
            <origin xyz="1.80411e-16 2.22045e-16 0" rpy="3.14159 -0 0" />
            <geometry>
                <mesh filename="package://dummy_joint:1.stl"/>
            </geometry>
            <material name="dummy_joint:1_material">
                <color rgba="0.972549 0.529412 0.00392157 1.0"/>
            </material>
        </collision>
        <inertial>
            <origin xyz="1.80886e-16 2.22535e-16 -0.00201266" rpy="0 0 0"/>
            <mass value="0.24179" />
            <inertia ixx="0.000251433" ixy="0" ixz="-5.58293e-20" iyy="0.000208335" iyz="3.46947e-20" izz="0.000342587" />
        </inertial>
    </link>

    <link name="member:1_5">
        <visual>
            <origin xyz="-9.71445e-17 2.22045e-16 -0.0133333" rpy="-1.5708 -1.5708 0" />
            <geometry>
                <mesh filename="package://member:1.stl"/>
            </geometry>
            <material name="member:1_material">
                <color rgba="0.717647 0.717647 0.717647 1.0"/>
            </material>
        </visual>
        <collision>
            <origin xyz="-9.71445e-17 2.22045e-16 -0.0133333" rpy="-1.5708 -1.5708 0" />
            <geometry>
                <mesh filename="package://member:1.stl"/>
            </geometry>
            <material name="member:1_material">
                <color rgba="0.717647 0.717647 0.717647 1.0"/>
            </material>
        </collision>
        <inertial>
            <origin xyz="1.77997e-08 0.514694 -0.0133333" rpy="0 0 0"/>
            <mass value="5.12617" />
            <inertia ixx="0.00413002" ixy="4.52589e-09" ixz="3.46766e-08" iyy="0.406687" iyz="-1.21553e-09" izz="0.406597" />
        </inertial>
    </link>

    <link name="member:1_6">
        <visual>
            <origin xyz="-2.77556e-17 8.32667e-17 -1" rpy="-1.50429e-17 7.25299e-17 0" />
            <geometry>
                <mesh filename="package://member:1.stl"/>
            </geometry>
            <material name="member:1_material">
                <color rgba="0.717647 0.717647 0.717647 1.0"/>
            </material>
        </visual>
        <collision>
            <origin xyz="-2.77556e-17 8.32667e-17 -1" rpy="-1.50429e-17 7.25299e-17 0" />
            <geometry>
                <mesh filename="package://member:1.stl"/>
            </geometry>
            <material name="member:1_material">
                <color rgba="0.717647 0.717647 0.717647 1.0"/>
            </material>
        </collision>
        <inertial>
            <origin xyz="8.227e-09 1.77997e-08 -0.485306" rpy="0 0 0"/>
            <mass value="5.12617" />
            <inertia ixx="0.406687" ixy="-1.21553e-09" ixz="4.52589e-09" iyy="0.406597" iyz="3.46766e-08" izz="0.00413002" />
        </inertial>
    </link>

    <link name="dummy_joint:1_6">
        <visual>
            <origin xyz="0 -3.46945e-18 -0.0133333" rpy="1.5708 1.5708 0" />
            <geometry>
                <mesh filename="package://dummy_joint:1.stl"/>
            </geometry>
            <material name="dummy_joint:1_material">
                <color rgba="0.972549 0.529412 0.00392157 1.0"/>
            </material>
        </visual>
        <collision>
            <origin xyz="0 -3.46945e-18 -0.0133333" rpy="1.5708 1.5708 0" />
            <geometry>
                <mesh filename="package://dummy_joint:1.stl"/>
            </geometry>
            <material name="dummy_joint:1_material">
                <color rgba="0.972549 0.529412 0.00392157 1.0"/>
            </material>
        </collision>
        <inertial>
            <origin xyz="-1.04932e-18 -0.00201266 -0.0133333" rpy="0 0 0"/>
            <mass value="0.24179" />
            <inertia ixx="0.000342587" ixy="-6.59495e-20" ixz="1.15649e-20" iyy="0.000251433" iyz="-2.79147e-20" izz="0.000208335" />
        </inertial>
    </link>

    <joint name="15" type="revolute">
        <origin xyz="-0.010479 0.0475077 0.036402" rpy="0.785396 -0.590722 0.492745" />
        <parent link="dummy_joint:1" />
        <child link="node:1" />
        <axis xyz="0 0 1"/>
        <limit effort="1" velocity="20" />
        <joint_properties friction="0.0"/>
    </joint>

    <joint name="14" type="revolute">
        <origin xyz="-0.0133333 4.85723e-17 -1" rpy="-1.5708 -0.785398 1.5708" />
        <parent link="member:1_6" />
        <child link="dummy_joint:1_6" />
        <axis xyz="0 0 1"/>
        <limit effort="1" velocity="20" />
        <joint_properties friction="0.0"/>
    </joint>

    <joint name="13" type="revolute">
        <origin xyz="-8.32667e-17 0.738001 -0.0133333" rpy="1.5708 -1.54604 -5.62071e-13" />
        <parent link="member:1_5" />
        <child link="member:1_6" />
        <axis xyz="0 0 1"/>
        <limit effort="1" velocity="20" />
        <joint_properties friction="0.0"/>
    </joint>

    <joint name="12" type="revolute">
        <origin xyz="0.0133333 2.22045e-16 2.22045e-16" rpy="-1.5708 0.803056 -1.5708" />
        <parent link="dummy_joint:1_5" />
        <child link="member:1_5" />
        <axis xyz="0 0 1"/>
        <limit effort="1" velocity="20" />
        <joint_properties friction="0.0"/>
    </joint>

    <joint name="11" type="revolute">
        <origin xyz="2.22045e-16 -5.55112e-17 0" rpy="-3.14159 -1.27676e-15 1.80835" />
        <parent link="node:1_3" />
        <child link="dummy_joint:1_5" />
        <axis xyz="0 0 1"/>
        <limit effort="1" velocity="20" />
        <joint_properties friction="0.0"/>
    </joint>

    <joint name="10" type="revolute">
        <origin xyz="-2.58474e-16 0 -0.0133333" rpy="-1.5708 1.31528 4.72205e-15" />
        <parent link="dummy_joint:1_4" />
        <child link="node:1_3" />
        <axis xyz="0 0 1"/>
        <limit effort="1" velocity="20" />
        <joint_properties friction="0.0"/>
    </joint>

    <joint name="9" type="revolute">
        <origin xyz="0.0133333 -1.11022e-16 -1" rpy="1.5708 0.80298 1.5708" />
        <parent link="member:1_4" />
        <child link="dummy_joint:1_4" />
        <axis xyz="0 0 1"/>
        <limit effort="1" velocity="20" />
        <joint_properties friction="0.0"/>
    </joint>

    <joint name="8" type="revolute">
        <origin xyz="-5.55112e-16 0.706085 -0.0133333" rpy="1.5708 -1.5708 0" />
        <parent link="member:1_3" />
        <child link="member:1_4" />
        <axis xyz="0 0 1"/>
        <limit effort="1" velocity="20" />
        <joint_properties friction="0.0"/>
    </joint>

    <joint name="7" type="revolute">
        <origin xyz="-0.0133333 1.11022e-16 0.000181962" rpy="1.5708 0.785472 -1.5708" />
        <parent link="dummy_joint:1_3" />
        <child link="member:1_3" />
        <axis xyz="0 0 1"/>
        <limit effort="1" velocity="20" />
        <joint_properties friction="0.0"/>
    </joint>

    <joint name="6" type="revolute">
        <origin xyz="-1.11022e-16 0 2.22045e-16" rpy="-3.14159 1.16573e-14 -1.07693" />
        <parent link="node:1_2" />
        <child link="dummy_joint:1_3" />
        <axis xyz="0 0 1"/>
        <limit effort="1" velocity="20" />
        <joint_properties friction="0.0"/>
    </joint>

    <joint name="5" type="revolute">
        <origin xyz="2.22045e-16 0 -0.0133333" rpy="1.5708 -1.07693 3.14159" />
        <parent link="dummy_joint:1_2" />
        <child link="node:1_2" />
        <axis xyz="0 0 1"/>
        <limit effort="1" velocity="20" />
        <joint_properties friction="0.0"/>
    </joint>

    <joint name="4" type="revolute">
        <origin xyz="0.0133333 -3.1225e-17 -1" rpy="-1.5708 0.785472 -1.5708" />
        <parent link="member:1_2" />
        <child link="dummy_joint:1_2" />
        <axis xyz="0 0 1"/>
        <limit effort="1" velocity="20" />
        <joint_properties friction="0.0"/>
    </joint>

    <joint name="3" type="revolute">
        <origin xyz="8.67362e-18 -0.768258 -0.0133333" rpy="-1.5708 -1.54603 2.22721e-12" />
        <parent link="member:1" />
        <child link="member:1_2" />
        <axis xyz="0 0 1"/>
        <limit effort="1" velocity="20" />
        <joint_properties friction="0.0"/>
    </joint>

    <joint name="2" type="revolute">
        <origin xyz="-0.0133333 2.08167e-17 0.000181962" rpy="1.5708 -0.785324 -1.5708" />
        <parent link="dummy_joint:1" />
        <child link="member:1" />
        <axis xyz="0 0 1"/>
        <limit effort="1" velocity="20" />
        <joint_properties friction="0.0"/>
    </joint>

    <joint name="1" type="revolute">
        <origin xyz="-0.010479 0.0475077 0.036402" rpy="2.35619 -0.590718 2.618" />
        <parent link="node:1" />
        <child link="dummy_joint:1" />
        <axis xyz="0 0 1"/>
        <limit effort="1" velocity="20" />
        <joint_properties friction="0.0"/>
    </joint>

</robot>
