<robot name="onshape">

    <material name="black">
        <color rgba="0 0 0 0.8"/>
    </material>
    <material name="cyan">
        <color rgba="0.0 1.0 1.0 1.0"/>
    </material>
    <material name="magenta">
        <color rgba="1.0 0.0 1.0 1.0"/>
    </material>
    <material name="yellow">
        <color rgba="1.0 1.0 0.0 1.0"/>
    </material>
    <link name="fake_dummy_body:1">
        <visual>
            <origin xyz="0 0 0" rpy="-0.785398 -0.61548 1.19113" />
            <geometry>
                <sphere radius="0.1"/>
            </geometry>
            <material name="black"/>
        </visual>
        <inertial>
            <origin xyz="0 0 0" rpy="0 0 0"/>
            <mass value="0.0737312" />
            <inertia ixx="0.00107839" ixy="-2.72753e-07" ixz="-6.10453e-07" iyy="0.00107874" iyz="-3.33412e-07" izz="0.00107814" />
        </inertial>
    </link>

    <link name="rev_joint:1">
        <visual>
            <origin xyz="0 0 0" rpy="3.14159 0 0" />
            <geometry>
                <cylinder radius="0.101" length="0.005"/>
            </geometry>
            <material name="cyan"/>
        </visual>
        <inertial>
            <origin xyz="0.0438631 0 -0.000928357" rpy="0 0 0"/>
            <mass value="0.00153243" />
            <inertia ixx="1.18928e-06" ixy="1.25481e-22" ixz="-8.58241e-08" iyy="2.31952e-06" iyz="1.38287e-22" izz="2.36022e-06" />
        </inertial>
    </link>

    <link name="member:1">
        <visual>
            <origin xyz="0 0 -0.5" rpy="0 -0 0" />
            <geometry>
                <mesh filename="package://member:1.stl"/>
            </geometry>
            <material name="member:1_material">
                <color rgba="0 0 1 1.0"/>
            </material>
        </visual>
        <collision>
            <origin xyz="0 0 -0.5" rpy="0 -0 0" />
            <geometry>
                <mesh filename="package://member:1.stl"/>
            </geometry>
            <material name="member:1_material">
                <color rgba="0 0 1 1.0"/>
            </material>
            <surface>
                <friction>
                <ode>
                    <mu>1</mu>
                    <mu2>0.5</mu2>
                </ode>
                </friction>
            </surface>
        </collision>
        <inertial>
            <origin xyz="0 0 -0.402703" rpy="0 0 0"/>
            <mass value="6.54356" />
            <inertia ixx="0.175312" ixy="-1.94635e-17" ixz="0" iyy="0.175312" iyz="1.82947e-09" izz="0.0193419" />
        </inertial>
    </link>

    <joint name="pri1" type="prismatic">
        <origin xyz="0.1 0 0" rpy="1.5708 0 -1.5708" />
        <parent link="rev_joint:1" />
        <child link="member:1" />
        <axis xyz="0 0 1"/>
        <limit effort="1" velocity="20" lower="-1" upper="0"/>
        <joint_properties friction="0.0"/>
    </joint>

    <joint name="rev1" type="revolute">
        <origin xyz="0 0 0" rpy="0.785398 0.61548 0.143931" />
        <parent link="fake_dummy_body:1" />
        <child link="rev_joint:1" />
        <axis xyz="0 0 1"/>
        <limit effort="1" velocity="20" lower="-1" upper="1"/>
        <joint_properties friction="0.0"/>
    </joint>

    <link name="rev_joint:1_2">
        <visual>
            <origin xyz="0 0 0" rpy="-3.14159 -0 -0" />
            <geometry>
                <cylinder radius="0.101" length="0.005"/>
            </geometry>
            <material name="magenta"/>
        </visual>
        <inertial>
            <origin xyz="0.0438631 0 -0.000928357" rpy="0 0 0"/>
            <mass value="0.00153243" />
            <inertia ixx="1.18928e-06" ixy="2.56032e-22" ixz="-8.58241e-08" iyy="2.31952e-06" iyz="-7.26909e-24" izz="2.36022e-06" />
        </inertial>
    </link>

    <link name="member:1_2">
        <visual>
            <origin xyz="0 0 -0.5" rpy="0 0 0" />
            <geometry>
                <mesh filename="package://member:1.stl"/>
            </geometry>
            <material name="member:1_material">
                <color rgba="0 0 1 1.0"/>
            </material>
        </visual>
        <collision>
            <origin xyz="0 0 -0.5" rpy="0 0 0" />
            <geometry>
                <mesh filename="package://member:1.stl"/>
            </geometry>
            <material name="member:1_material">
                <color rgba="0 0 1 1.0"/>
            </material>
            <surface>
                <friction>
                <ode>
                    <mu>1</mu>
                    <mu2>0.5</mu2>
                </ode>
                </friction>
            </surface>
        </collision>
        <inertial>
            <origin xyz="-9.8046e-17 0 -0.402703" rpy="0 0 0"/>
            <mass value="6.54356" />
            <inertia ixx="0.175312" ixy="-9.73176e-18" ixz="3.78533e-17" iyy="0.175312" iyz="1.82947e-09" izz="0.0193419" />
        </inertial>
    </link>

    <joint name="pri2" type="prismatic">
        <origin xyz="0.1 0 0" rpy="1.5708 0 -1.5708" />
        <parent link="rev_joint:1_2" />
        <child link="member:1_2" />
        <axis xyz="0 0 1"/>
        <limit effort="1" velocity="20" lower="-1" upper="0"/>
        <joint_properties friction="0.0"/>
    </joint>

    <joint name="rev2" type="revolute">
        <origin xyz="0 0 0" rpy="0.785398 0.61548 -1.95046" />
        <parent link="fake_dummy_body:1" />
        <child link="rev_joint:1_2" />
        <axis xyz="0 0 1"/>
        <limit effort="1" velocity="20" lower="-1" upper="1"/>
        <joint_properties friction="0.0"/>
    </joint>

    <link name="rev_joint:1_3">
        <visual>
            <origin xyz="0 0 0" rpy="-3.14159 -0 0" />
            <geometry>
                <cylinder radius="0.101" length="0.005"/>
            </geometry>
            <material name="yellow"/>
        </visual>
        <inertial>
            <origin xyz="0.0438631 0 -0.000928357" rpy="0 0 0"/>
            <mass value="0.00153243" />
            <inertia ixx="1.18928e-06" ixy="-4.76419e-24" ixz="-8.58241e-08" iyy="2.31952e-06" iyz="2.59777e-22" izz="2.36022e-06" />
        </inertial>
    </link>

    <link name="member:1_3">
        <visual>
            <origin xyz="0 0 -0.5" rpy="0 -0 0" />
            <geometry>
                <mesh filename="package://member:1.stl"/>
            </geometry>
            <material name="member:1_material">
                <color rgba="0 0 1 1.0"/>
            </material>
        </visual>
        <collision>
            <origin xyz="0 0 -0.5" rpy="0 -0 0" />
            <geometry>
                <mesh filename="package://member:1.stl"/>
            </geometry>
            <material name="member:1_material">
                <color rgba="0 0 1 1.0"/>
            </material>
            <surface>
                <friction>
                <ode>
                    <mu>1</mu>
                    <mu2>0.5</mu2>
                </ode>
                </friction>
            </surface>
        </collision>
        <inertial>
            <origin xyz="0 0 -0.402703" rpy="0 0 0"/>
            <mass value="6.54356" />
            <inertia ixx="0.175312" ixy="-1.94635e-17" ixz="0" iyy="0.175312" iyz="1.82947e-09" izz="0.0193419" />
        </inertial>
    </link>

    <joint name="pri3" type="prismatic">
        <origin xyz="0.1 0 0" rpy="-3.14159 1.5708 0" />
        <parent link="rev_joint:1_3" />
        <child link="member:1_3" />
        <axis xyz="0 0 1"/>
        <limit effort="1" velocity="20" lower="-1" upper="0"/>
        <joint_properties friction="0.0"/>
    </joint>

    <joint name="rev3" type="revolute">
        <origin xyz="0 0 0" rpy="-2.35619 0.61548 2.23833" />
        <parent link="fake_dummy_body:1" />
        <child link="rev_joint:1_3" />
        <axis xyz="0 0 1"/>
        <limit effort="1" velocity="20" lower="-1" upper="1"/>
        <joint_properties friction="0.0"/>
    </joint>

    <link name="rev_joint:1_4">
        <visual>
            <origin xyz="0 0 0" rpy="3.14159 -0 0" />
            <geometry>
                <cylinder radius="0.01" length="0.001"/>
            </geometry>
            <material name="rev_joint:1_material">
                <color rgba="0.980392 0.713725 0.00392157 1.0"/>
            </material>
        </visual>
        <inertial>
            <origin xyz="0.0438631 0 -0.000928357" rpy="0 0 0"/>
            <mass value="0.00153243" />
            <inertia ixx="1.18928e-06" ixy="7.07826e-23" ixz="-8.58241e-08" iyy="2.31952e-06" iyz="-3.93301e-22" izz="2.36022e-06" />
        </inertial>
    </link>

    <link name="member:1_4">
        <visual>
            <origin xyz="0 0 -0.5" rpy="0 -0 -0" />
            <geometry>
                <mesh filename="package://member:1.stl"/>
            </geometry>
            <material name="member:1_material">
                <color rgba="0 0 1 1.0"/>
            </material>
        </visual>
        <collision>
            <origin xyz="0 0 -0.5" rpy="0 -0 -0" />
            <geometry>
                <mesh filename="package://member:1.stl"/>
            </geometry>
            <material name="member:1_material">
                <color rgba="0 0 1 1.0"/>
            </material>
            <surface>
                <friction>
                <ode>
                    <mu>1</mu>
                    <mu2>0.5</mu2>
                </ode>
                </friction>
            </surface>
        </collision>
        <inertial>
            <origin xyz="0 0 -0.402703" rpy="0 0 0"/>
            <mass value="6.54356" />
            <inertia ixx="0.175312" ixy="-5.30476e-24" ixz="-1.83898e-17" iyy="0.175312" iyz="1.82947e-09" izz="0.0193419" />
        </inertial>
    </link>

    <joint name="pri4" type="prismatic">
        <origin xyz="0.1 0 0" rpy="-3.14159 1.5708 0" />
        <parent link="rev_joint:1_4" />
        <child link="member:1_4" />
        <axis xyz="0 0 1"/>
        <limit effort="1" velocity="20" lower="-1" upper="0"/>
        <joint_properties friction="0.0"/>
    </joint>

    <joint name="rev4" type="revolute">
        <origin xyz="0 0 0" rpy="-0.785398 -0.61548 -0.903267" />
        <parent link="fake_dummy_body:1" />
        <child link="rev_joint:1_4" />
        <axis xyz="0 0 1"/>
        <limit effort="1" velocity="20" lower="-1" upper="1"/>
        <joint_properties friction="0.0"/>
    </joint>

    <link name="rev_joint:1_5">
        <visual>
            <origin xyz="0 0 0" rpy="3.14159 0 0" />
            <geometry>
                <cylinder radius="0.01" length="0.001"/>
            </geometry>
            <material name="rev_joint:1_material">
                <color rgba="0.980392 0.713725 0.00392157 1.0"/>
            </material>
        </visual>
        <inertial>
            <origin xyz="0.0438631 0 -0.000928357" rpy="0 0 0"/>
            <mass value="0.00153243" />
            <inertia ixx="1.18928e-06" ixy="2.64074e-22" ixz="-8.58241e-08" iyy="2.31952e-06" iyz="-1.90568e-23" izz="2.36022e-06" />
        </inertial>
    </link>

    <link name="member:1_5">
        <visual>
            <origin xyz="0 0 -0.5" rpy="0 -0 0" />
            <geometry>
                <mesh filename="package://member:1.stl"/>
            </geometry>
            <material name="member:1_material">
                <color rgba="0 0 1 1.0"/>
            </material>
        </visual>
        <collision>
            <origin xyz="0 0 -0.5" rpy="0 -0 0" />
            <geometry>
                <mesh filename="package://member:1.stl"/>
            </geometry>
            <material name="member:1_material">
                <color rgba="0 0 1 1.0"/>
            </material>
            <surface>
                <friction>
                <ode>
                    <mu>1</mu>
                    <mu2>0.5</mu2>
                </ode>
                </friction>
            </surface>
        </collision>
        <inertial>
            <origin xyz="0 0 -0.402703" rpy="0 0 0"/>
            <mass value="6.54356" />
            <inertia ixx="0.175312" ixy="2.91953e-17" ixz="-8.65807e-18" iyy="0.175312" iyz="1.82947e-09" izz="0.0193419" />
        </inertial>
    </link>

    <joint name="pri5" type="prismatic">
        <origin xyz="0.1 0 0" rpy="1.5708 0 -1.5708" />
        <parent link="rev_joint:1_5" />
        <child link="member:1_5" />
        <axis xyz="0 0 1"/>
        <limit effort="1" velocity="20" lower="-1" upper="0"/>
        <joint_properties friction="0.0"/>
    </joint>

    <joint name="rev5" type="revolute">
        <origin xyz="0 0 0" rpy="2.35619 -0.61548 1.19113" />
        <parent link="fake_dummy_body:1" />
        <child link="rev_joint:1_5" />
        <axis xyz="0 0 1"/>
        <limit effort="1" velocity="20" lower="-1" upper="1"/>
        <joint_properties friction="0.0"/>
    </joint>

    <link name="rev_joint:1_6">
        <visual>
            <origin xyz="0 0 0" rpy="-3.14159 -0 -0" />
            <geometry>
                <cylinder radius="0.01" length="0.001"/>
            </geometry>
            <material name="rev_joint:1_material">
                <color rgba="0.980392 0.713725 0.00392157 1.0"/>
            </material>
        </visual>
        <inertial>
            <origin xyz="0.0438631 0 -0.000928357" rpy="0 0 0"/>
            <mass value="0.00153243" />
            <inertia ixx="1.18928e-06" ixy="2.51268e-22" ixz="-8.58241e-08" iyy="2.31952e-06" iyz="1.23749e-22" izz="2.36022e-06" />
        </inertial>
    </link>

    <link name="member:1_6">
        <visual>
            <origin xyz="0 0 -0.5" rpy="0 0 0" />
            <geometry>
                <mesh filename="package://member:1.stl"/>
            </geometry>
            <material name="member:1_material">
                <color rgba="0 0 1 1.0"/>
            </material>
        </visual>
        <collision>
            <origin xyz="0 0 -0.5" rpy="0 0 0" />
            <geometry>
                <mesh filename="package://member:1.stl"/>
            </geometry>
            <material name="member:1_material">
                <color rgba="0 0 1 1.0"/>
            </material>
            <surface>
                <friction>
                <ode>
                    <mu>1</mu>
                    <mu2>0.5</mu2>
                </ode>
                </friction>
            </surface>
        </collision>
        <inertial>
            <origin xyz="0 0 -0.402703" rpy="0 0 0"/>
            <mass value="6.54356" />
            <inertia ixx="0.175312" ixy="-1.09142e-23" ixz="1.83898e-17" iyy="0.175312" iyz="1.82947e-09" izz="0.0193419" />
        </inertial>
    </link>

    <joint name="pri6" type="prismatic">
        <origin xyz="0.1 0 0" rpy="1.5708 0 -1.5708" />
        <parent link="rev_joint:1_6" />
        <child link="member:1_6" />
        <axis xyz="0 0 1"/>
        <limit effort="1" velocity="20" lower="-1" upper="0"/>
        <joint_properties friction="0.0"/>
    </joint>

    <joint name="rev6" type="revolute">
        <origin xyz="0 0 0" rpy="2.35619 -0.61548 -2.99766" />
        <parent link="fake_dummy_body:1" />
        <child link="rev_joint:1_6" />
        <axis xyz="0 0 1"/>
        <limit effort="1" velocity="20" lower="-1" upper="1"/>
        <joint_properties friction="0.0"/>
    </joint>


</robot>
